Workbook

Sheet Customer Names
A1: Customer ID | B1: name | C1: Tiltle | D1: First Name | E1: Last Name
A2: Id1 | B2: Hawks, | C2: Ms. | D2: Kelly
A3: Id2 | B3: Lehner, | C3: Mr. | D3: Matthew | E3: D
A4: Id3 | B4: Lu, | C4: Mr. | D4: Phil
A5: Id4 | B5: Osborne, | C5: Ms. | D5: Kelsey
A6: Id5 | B6: Kadala, | C6: Ms. | D6: Kristyn
A7: Id6 | B7: Baker, | C7: Mr. | D7: Russell | E7: B.
A8: Id7 | B8: Macpherson, | C8: Mr. | D8: Scott
A9: Id8 | B9: Hallman, | C9: Mr. | D9: Stephen
A10: Id9 | B10: Moran, | C10: Mr. | D10: Patrick | E10: R.
A11: Id10 | B11: Benner, | C11: Ms. | D11: Brooke | E11: N.
A12: Id11 | B12: Fierro | C12: Ms. | D12: Paola | E12: Andrea
A13: Id12 | B13: Franz, | C13: Mr. | D13: David
A14: Id13 | B14: Foster, | C14: Mr. | D14: Wade
A15: Id14 | B15: Tenorio, | C15: Mr. | D15: Franklin
A16: Id15 | B16: Rios, | C16: Ms. | D16: Leilani | E16: M.
A17: Id16 | B17: Viau-Dupuis, | C17: Mr. | D17: Philippe
A18: Id17 | B18: Cronin, | C18: Ms. | D18: Jennifer | E18: A.
A19: Id18 | B19: Noordstar, | C19: Ms. | D19: Christina | E19: M.
A20: Id19 | B20: Boudalia, | C20: Mr. | D20: Said | E20: Sr.
A21: Id20 | B21: Flor, | C21: Mr. | D21: John
A22: Id21 | B22: Fennon, | C22: Mr. | D22: Myles
A23: Id22 | B23: Hribar, | C23: Ms. | D23: Madelyn | E23: C
A24: Id23 | B24: Tassello, | C24: Ms. | D24: Nicole
A25: Id24 | B25: Mauricette, | C25: Mr. | D25: Eric | E25: A.
A26: Id25 | B26: Garcia, | C26: Mr. | D26: Emiliano | E26: I.
A27: Id26 | B27: Airoldi, | C27: Mr. | D27: Adam
A28: Id27 | B28: Cater-Cyker, | C28: Mr. | D28: Zach
A29: Id28 | B29: Hamm, | C29: Ms. | D29: Stephanie | E29: W.
A30: Id29 | B30: Cox, | C30: Mr. | D30: Stephen
A31: Id30 | B31: Sachrajda, | C31: Ms. | D31: Natalie
A32: Id31 | B32: Gareri, | C32: Ms. | D32: Nicole | E32: J.
A33: Id32 | B33: Welch, | C33: Mr. | D33: Jefferson | E33: D
A34: Id33 | B34: Prindiville, | C34: Mr. | D34: Brendan | E34: D.
A35: Id34 | B35: Kincaid, | C35: Ms. | D35: Courtney
A36: Id35 | B36: Bruestle, | C36: Ms. | D36: Sydney | E36: L.
A37: Id36 | B37: Lachance, | C37: Mr. | D37: Julien
A38: Id37 | B38: Eason, | C38: Mr. | D38: Ryan | E38: M
A39: Id38 | B39: Grummon, | C39: Ms. | D39: Anna | E39: H.
A40: Id39 | B40: Vanwechel, | C40: Ms. | D40: Samantha
...

Sheet Medical Examinations (2)
A1: Customer ID | B1: BMI | C1: HBA1C | D1: Heart Issues | E1: Any Transplants | F1: Cancer history | G1: NumberOfMajorSurgeries | H1: smoker | I1: Weight Status | J1: Diabets Status
A2: Id1 | B2: 47.41 | C2: 7.47 | D2: No | E2: No | F2: No | G2: 0 | H2: yes | I2: =IF(B2<18.5,"Underweight",IF(B2<25,"Normalweight",IF(B2<30,"Overweight","Obesity"))) -> Obesity | J2: =IF(C1<5.7,"Normal",IF(C1<6.5,"Prediabetes","Diabetes")) -> Diabetes
A3: Id2 | B3: 30.36 | C3: 5.77 | D3: No | E3: No | F3: No | G3: 0 | H3: yes | I3: =IF(B3<18.5,"Underweight",IF(B3<25,"Normalweight",IF(B3<30,"Overweight","Obesity"))) -> Obesity | J3: =IF(C2<5.7,"Normal",IF(C2<6.5,"Prediabetes","Diabetes")) -> Diabetes
A4: Id3 | B4: 34.485 | C4: 11.87 | D4: yes | E4: No | F4: No | G4: 2 | H4: yes | I4: =IF(B4<18.5,"Underweight",IF(B4<25,"Normalweight",IF(B4<30,"Overweight","Obesity"))) -> Obesity | J4: =IF(C3<5.7,"Normal",IF(C3<6.5,"Prediabetes","Diabetes")) -> Prediabetes
A5: Id4 | B5: 38.095 | C5: 6.05 | D5: No | E5: No | F5: No | G5: 0 | H5: yes | I5: =IF(B5<18.5,"Underweight",IF(B5<25,"Normalweight",IF(B5<30,"Overweight","Obesity"))) -> Obesity | J5: =IF(C4<5.7,"Normal",IF(C4<6.5,"Prediabetes","Diabetes")) -> Diabetes
A6: Id5 | B6: 35.53 | C6: 5.45 | D6: No | E6: No | F6: No | G6: 0 | H6: yes | I6: =IF(B6<18.5,"Underweight",IF(B6<25,"Normalweight",IF(B6<30,"Overweight","Obesity"))) -> Obesity | J6: =IF(C5<5.7,"Normal",IF(C5<6.5,"Prediabetes","Diabetes")) -> Prediabetes
A7: Id6 | B7: 32.8 | C7: 6.59 | D7: No | E7: No | F7: No | G7: 0 | H7: yes | I7: =IF(B7<18.5,"Underweight",IF(B7<25,"Normalweight",IF(B7<30,"Overweight","Obesity"))) -> Obesity | J7: =IF(C6<5.7,"Normal",IF(C6<6.5,"Prediabetes","Diabetes")) -> Normal
A8: Id7 | B8: 36.4 | C8: 6.07 | D8: No | E8: No | F8: No | G8: 0 | H8: yes | I8: =IF(B8<18.5,"Underweight",IF(B8<25,"Normalweight",IF(B8<30,"Overweight","Obesity"))) -> Obesity | J8: =IF(C7<5.7,"Normal",IF(C7<6.5,"Prediabetes","Diabetes")) -> Diabetes
A9: Id8 | B9: 36.96 | C9: 7.93 | D9: No | E9: No | F9: No | G9: 3 | H9: yes | I9: =IF(B9<18.5,"Underweight",IF(B9<25,"Normalweight",IF(B9<30,"Overweight","Obesity"))) -> Obesity | J9: =IF(C8<5.7,"Normal",IF(C8<6.5,"Prediabetes","Diabetes")) -> Prediabetes
A10: Id9 | B10: 41.14 | C10: 9.58 | D10: yes | E10: No | F10: Yes | G10: 1 | H10: yes | I10: =IF(B10<18.5,"Underweight",IF(B10<25,"Normalweight",IF(B10<30,"Overweight","Obesity"))) -> Obesity | J10: =IF(C9<5.7,"Normal",IF(C9<6.5,"Prediabetes","Diabetes")) -> Diabetes
A11: Id10 | B11: 38.06 | C11: 10.79 | D11: No | E11: No | F11: No | G11: 0 | H11: yes | I11: =IF(B11<18.5,"Underweight",IF(B11<25,"Normalweight",IF(B11<30,"Overweight","Obesity"))) -> Obesity | J11: =IF(C10<5.7,"Normal",IF(C10<6.5,"Prediabetes","Diabetes")) -> Diabetes
A12: Id11 | B12: 37.7 | C12: 5.96 | D12: yes | E12: No | F12: No | G12: 2 | H12: yes | I12: =IF(B12<18.5,"Underweight",IF(B12<25,"Normalweight",IF(B12<30,"Overweight","Obesity"))) -> Obesity | J12: =IF(C11<5.7,"Normal",IF(C11<6.5,"Prediabetes","Diabetes")) -> Diabetes
A13: Id12 | B13: 42.13 | C13: 11.9 | D13: No | E13: No | F13: No | G13: 0 | H13: yes | I13: =IF(B13<18.5,"Underweight",IF(B13<25,"Normalweight",IF(B13<30,"Overweight","Obesity"))) -> Obesity | J13: =IF(C12<5.7,"Normal",IF(C12<6.5,"Prediabetes","Diabetes")) -> Prediabetes
... A2336: Id2335 | B2336: 17.58 | C2336: 4.51 | D2336: No | E2336: No | F2336: No | G2336: 1 | H2336: No | I2336: =IF(B2336<18.5,"Underweight",IF(B2336<25,"Normalweight",IF(B2336<30,"Overweight","Obesity"))) -> Underweight | J2336: =IF(C2335<5.7,"Normal",IF(C2335<6.5,"Prediabetes","Diabetes")) -> Normal
J2337: =IF(C2336<5.7,"Normal",IF(C2336<6.5,"Prediabetes","Diabetes")) -> Normal
J2338: =IF(C2337<5.7,"Normal",IF(C2337<6.5,"Prediabetes","Diabetes")) -> Normal
J2339: =IF(C2338<5.7,"Normal",IF(C2338<6.5,"Prediabetes","Diabetes")) -> Normal
J2340: =IF(C2339<5.7,"Normal",IF(C2339<6.5,"Prediabetes","Diabetes")) -> Normal

Sheet Hospitalisation Details (2)
A1: Customer ID | B1: year | C1: month | D1: date | E1: children | F1: charges | G1: Hospital tier | H1: City tier | I1: State ID | J1: Date of Birth | K1: Age
A2: Id2335 | B2: 1992 | C2: Jul | D2: 9 | E2: 0 | F2: 563.84 | G2: tier - 2 | H2: tier - 3 | I2: R1013 | J2: =DATE(Hospitalisation_Details[[#This Row],[year]],MONTH("1-"&Hospitalisation_Details[[#This Row],[month]]&"-2000"),Hospitalisation_Details[[#This Row],[date]]) -> 33794 | K2: =YEAR(DATE(2023,6,8))-YEAR(J2)-IF(DATE(2023,6,8)<DATE(2023,6,8)<DATE(2023,MONTH(J2),DAY(J2)),1,0) -> 31
A3: Id2334 | B3: 1992 | C3: Nov | D3: 30 | E3: 0 | F3: 570.62 | G3: tier - 2 | H3: tier - 1 | I3: R1013 | J3: =DATE(Hospitalisation_Details[[#This Row],[year]],MONTH("1-"&Hospitalisation_Details[[#This Row],[month]]&"-2000"),Hospitalisation_Details[[#This Row],[date]]) -> 33938 | K3: =YEAR(DATE(2023,6,8))-YEAR(J3)-IF(DATE(2023,6,8)<DATE(2023,6,8)<DATE(2023,MONTH(J3),DAY(J3)),1,0) -> 31
A4: Id2333 | B4: 1993 | C4: Jun | D4: 30 | E4: 0 | F4: 600 | G4: tier - 2 | H4: tier - 1 | I4: R1013 | J4: =DATE(Hospitalisation_Details[[#This Row],[year]],MONTH("1-"&Hospitalisation_Details[[#This Row],[month]]&"-2000"),Hospitalisation_Details[[#This Row],[date]]) -> 34150 | K4: =YEAR(DATE(2023,6,8))-YEAR(J4)-IF(DATE(2023,6,8)<DATE(2023,6,8)<DATE(2023,MONTH(J4),DAY(J4)),1,0) -> 30
A5: Id2332 | B5: 1992 | C5: Sep | D5: 13 | E5: 0 | F5: 604.54 | G5: tier - 3 | H5: tier - 3 | I5: R1013 | J5: =DATE(Hospitalisation_Details[[#This Row],[year]],MONTH("1-"&Hospitalisation_Details[[#This Row],[month]]&"-2000"),Hospitalisation_Details[[#This Row],[date]]) -> 33860 | K5: =YEAR(DATE(2023,6,8))-YEAR(J5)-IF(DATE(2023,6,8)<DATE(2023,6,8)<DATE(2023,MONTH(J5),DAY(J5)),1,0) -> 31
A6: Id2331 | B6: 1998 | C6: Jul | D6: 27 | E6: 0 | F6: 637.26 | G6: tier - 3 | H6: tier - 3 | I6: R1013 | J6: =DATE(Hospitalisation_Details[[#This Row],[year]],MONTH("1-"&Hospitalisation_Details[[#This Row],[month]]&"-2000"),Hospitalisation_Details[[#This Row],[date]]) -> 36003 | K6: =YEAR(DATE(2023,6,8))-YEAR(J6)-IF(DATE(2023,6,8)<DATE(2023,6,8)<DATE(2023,MONTH(J6),DAY(J6)),1,0) -> 25
A7: Id2330 | B7: 2001 | C7: Nov | D7: 20 | E7: 0 | F7: 646.14 | G7: tier - 3 | H7: tier - 3 | I7: R1012 | J7: =DATE(Hospitalisation_Details[[#This Row],[year]],MONTH("1-"&Hospitalisation_Details[[#This Row],[month]]&"-2000"),Hospitalisation_Details[[#This Row],[date]]) -> 37215 | K7: =YEAR(DATE(2023,6,8))-YEAR(J7)-IF(DATE(2023,6,8)<DATE(2023,6,8)<DATE(2023,MONTH(J7),DAY(J7)),1,0) -> 22
A8: Id2329 | B8: 1993 | C8: Jun | D8: 1 | E8: 0 | F8: 650 | G8: tier - 3 | H8: tier - 3 | I8: R1013 | J8: =DATE(Hospitalisation_Details[[#This Row],[year]],MONTH("1-"&Hospitalisation_Details[[#This Row],[month]]&"-2000"),Hospitalisation_Details[[#This Row],[date]]) -> 34121 | K8: =YEAR(DATE(2023,6,8))-YEAR(J8)-IF(DATE(2023,6,8)<DATE(2023,6,8)<DATE(2023,MONTH(J8),DAY(J8)),1,0) -> 30
A9: Id2328 | B9: 1995 | C9: Jul | D9: 4 | E9: 0 | F9: 650 | G9: tier - 3 | H9: tier - 3 | I9: R1013 | J9: =DATE(Hospitalisation_Details[[#This Row],[year]],MONTH("1-"&Hospitalisation_Details[[#This Row],[month]]&"-2000"),Hospitalisation_Details[[#This Row],[date]]) -> 34884 | K9: =YEAR(DATE(2023,6,8))-YEAR(J9)-IF(DATE(2023,6,8)<DATE(2023,6,8)<DATE(2023,MONTH(J9),DAY(J9)),1,0) -> 28
A10: Id2327 | B10: 2002 | C10: Nov | D10: 29 | E10: 0 | F10: 668 | G10: tier - 3 | H10: tier - 2 | I10: R1012 | J10: =DATE(Hospitalisation_Details[[#This Row],[year]],MONTH("1-"&Hospitalisation_Details[[#This Row],[month]]&"-2000"),Hospitalisation_Details[[#This Row],[date]]) -> 37589 | K10: =YEAR(DATE(2023,6,8))-YEAR(J10)-IF(DATE(2023,6,8)<DATE(2023,6,8)<DATE(2023,MONTH(J10),DAY(J10)),1,0) -> 21
A11: Id2326 | B11: 1997 | C11: Nov | D11: 9 | E11: 0 | F11: 670 | G11: tier - 3 | H11: tier - 3 | I11: R1013 | J11: =DATE(Hospitalisation_Details[[#This Row],[year]],MONTH("1-"&Hospitalisation_Details[[#This Row],[month]]&"-2000"),Hospitalisation_Details[[#This Row],[date]]) -> 35743 | K11: =YEAR(DATE(2023,6,8))-YEAR(J11)-IF(DATE(2023,6,8)<DATE(2023,6,8)<DATE(2023,MONTH(J11),DAY(J11)),1,0) -> 26
A12: Id2325 | B12: 2001 | C12: Sep | D12: 12 | E12: 0 | F12: 687.54 | G12: tier - 3 | H12: tier - 2 | I12: R1013 | J12: =DATE(Hospitalisation_Details[[#This Row],[year]],MONTH("1-"&Hospitalisation_Details[[#This Row],[month]]&"-2000"),Hospitalisation_Details[[#This Row],[date]]) -> 37146 | K12: =YEAR(DATE(2023,6,8))-YEAR(J12)-IF(DATE(2023,6,8)<DATE(2023,6,8)<DATE(2023,MONTH(J12),DAY(J12)),1,0) -> 22
A13: Id2324 | B13: 1999 | C13: Dec | D13: 26 | E13: 0 | F13: 700 | G13: tier-2 | H13: tier - 3 | I13: R1013 | J13: =DATE(Hospitalisation_Details[[#This Row],[year]],MONTH("1-"&Hospitalisation_Details[[#This Row],[month]]&"-2000"),Hospitalisation_Details[[#This Row],[date]]) -> 36520 | K13: =YEAR(DATE(2023,6,8))-YEAR(J13)-IF(DATE(2023,6,8)<DATE(2023,6,8)<DATE(2023,MONTH(J13),DAY(J13)),1,0) -> 24
... A2344: Id1 | B2344: 1968 | C2344: Oct | D2344: 12 | E2344: 0 | F2344: 63770.43 | G2344: tier - 1 | H2344: tier - 3 | I2344: R1013 | J2344: =DATE(Hospitalisation_Details[[#This Row],[year]],MONTH("1-"&Hospitalisation_Details[[#This Row],[month]]&"-2000"),Hospitalisation_Details[[#This Row],[date]]) -> 25123 | K2344: =YEAR(DATE(2023,6,8))-YEAR(J2344)-IF(DATE(2023,6,8)<DATE(2023,6,8)<DATE(2023,MONTH(J2344),DAY(J2344)),1,0) -> 55

Sheet Health care
A1: CUSTOMER+A1:C2334 ID | B1: BMI | C1: HBAIC | D1: Heart Issues | E1: Any Transplants | F1: Cancer History | G1: Number of major surgeries | H1: Smoker | I1: Year | J1: Month | K1: Date | L1: Hospital tier | M1: City tier | N1: State ID | O1: Date of Birth | P1: Age | Q1: Title | R1: First Name | S1: Last Name | T1: Charges | U1: Weight Status | V1: Diabetes status | X1: Category | Y1: Count | AJ1: Transplant History | AK1: Total major Surgeries | AL1: Average BhA1C | AR1: Weight status | AS1: Average Charges | AT1: Diabetes status | AU1: Average Charges | BB1: State ID | BC1: tier 1 | BD1: tier 2 | BE1: tier 3
A2: Id2335 | B2: =VLOOKUP($A2,'[1]Medical Examinations'!$A:$J,2,FALSE) -> 17.58 | C2: =VLOOKUP($A2,'[1]Medical Examinations'!$A:$J,3,FALSE) -> 4.51 | D2: =VLOOKUP($A2,'[3]Medical Examinations'!$A:$J,4,FALSE) -> No | E2: =VLOOKUP($A2,'[1]Medical Examinations'!$A:$J,5,FALSE) -> No | F2: =VLOOKUP($A2,'[1]Medical Examinations'!$A:$J,6,FALSE) -> No | G2: =VLOOKUP($A2,'[3]Medical Examinations'!$A:$J,7,FALSE) -> 1 | H2: =VLOOKUP($A2,'[1]Medical Examinations'!$A:$J,8,FALSE) -> No | I2: =VLOOKUP($A2,'[2]Hospitalisation Details'!$A:$K,2,FALSE) -> 1992 | J2: =VLOOKUP($A2,'[2]Hospitalisation Details'!$A:$K,3,FALSE) -> Jul | K2: =VLOOKUP($A2,'[2]Hospitalisation Details'!$A:$K,4,FALSE) -> 9 | L2: =VLOOKUP($A2,'[2]Hospitalisation Details'!$A:$K,7,FALSE) -> tier - 2 | M2: =VLOOKUP($A2,'[2]Hospitalisation Details'!A:$K,8,FALSE) -> tier - 3 | N2: =VLOOKUP($A2,'[2]Hospitalisation Details'!$A:$K,9,FALSE) -> R1013 | O2: =_xlfn.XLOOKUP($A2,'[2]Hospitalisation Details'!$A:$A,'[2]Hospitalisation Details'!$J:$J,"") -> 0 | P2: =VLOOKUP($A2,'[2]Hospitalisation Details'!A:$K,11,FALSE) -> 0 | Q2: =VLOOKUP($A2,'Customer Names'!$A:E,3,FALSE) -> Mr. | R2: =VLOOKUP($A2,'Customer Names'!$A:$E,4,FALSE) -> Aaron | S2: =VLOOKUP($A2,'Customer Names'!$A:$E,5,FALSE) -> K | T2: =VLOOKUP($A2,'[2]Hospitalisation Details'!$A:$K,6,FALSE) -> 563.84 | U2: =IF(B2<18.5,"Underweight",IF(B2<25,"Normalweight",IF(B2<30,"Overweight","Obesity"))) -> Underweight | V2: =IF(C2<5.7,"Normal",IF(C2<6.5,"Prediabetes","Diabetes")) -> Normal | X2: Smoker+Cancer | Y2: =COUNTIFS($H:$H,"Yes",$F:$F,"Yes") -> 84 | AJ2: Yes | AK2: =SUMIF($E:$E,"Yes",$G:$G) -> 162 | AL2: =AVERAGEIF($E:$E,"Yes",$C:$C) -> 5.1876389 | AR2: Underweight | AS2: =AVERAGEIF($U:$U,"Underweight",$T:$T) -> 6899.3175 | AT2: Normal | AU2: =AVERAGEIF($V:$V,"Normal",$T:$T) -> 12090.723 | BB2: R1013 | BC2: =IFERROR(AVERAGEIFS('Health care'!$T:$T,'Health care'!$N:$N,$BB2,'Health care'!$L:$L,"*tier*1*"),0) -> 31371.853 | BD2: =IFERROR(AVERAGEIFS('Health care'!$T:$T,'Health care'!$N:$N,$BB2,'Health care'!$L:$L,"*tier*2*"),0) -> 8459.9777 | BE2: =IFERROR(AVERAGEIFS('Health care'!$T:$T,'Health care'!$N:$N,$BB2,'Health care'!$L:$L,"*tier*3*"),0) -> 6694.6064
A3: Id2334 | B3: =VLOOKUP($A3,'[1]Medical Examinations'!$A:$J,2,FALSE) -> 17.6 | C3: =VLOOKUP($A3,'[1]Medical Examinations'!$A:$J,3,FALSE) -> 4.39 | D3: =VLOOKUP($A3,'[3]Medical Examinations'!$A:$J,4,FALSE) -> No | E3: =VLOOKUP($A3,'[1]Medical Examinations'!$A:$J,5,FALSE) -> No | F3: =VLOOKUP($A3,'[1]Medical Examinations'!$A:$J,6,FALSE) -> No | G3: =VLOOKUP($A3,'[3]Medical Examinations'!$A:$J,7,FALSE) -> 1 | H3: =VLOOKUP($A3,'[1]Medical Examinations'!$A:$J,8,FALSE) -> No | I3: =VLOOKUP($A3,'[2]Hospitalisation Details'!$A:$K,2,FALSE) -> 1992 | J3: =VLOOKUP($A3,'[2]Hospitalisation Details'!$A:$K,3,FALSE) -> Nov | K3: =VLOOKUP($A3,'[2]Hospitalisation Details'!$A:$K,4,FALSE) -> 30 | L3: =VLOOKUP($A3,'[2]Hospitalisation Details'!$A:$K,7,FALSE) -> tier - 2 | M3: =VLOOKUP($A3,'[2]Hospitalisation Details'!A:$K,8,FALSE) -> tier - 1 | N3: =VLOOKUP($A3,'[2]Hospitalisation Details'!$A:$K,9,FALSE) -> R1013 | O3: =VLOOKUP($A3,'[2]Hospitalisation Details'!$A:$K,10,FALSE) -> 0 | P3: =VLOOKUP($A3,'[2]Hospitalisation Details'!A:$K,11,FALSE) -> 0 | Q3: =VLOOKUP($A3,'Customer Names'!$A:E,3,FALSE) -> Mr. | R3: =VLOOKUP($A3,'Customer Names'!$A:$E,4,FALSE) -> Evan | S3: =VLOOKUP($A3,'Customer Names'!$A:$E,5,FALSE) -> P | T3: =VLOOKUP($A3,'[2]Hospitalisation Details'!$A:$K,6,FALSE) -> 570.62 | U3: =IF(B3<18.5,"Underweight",IF(B3<25,"Normalweight",IF(B3<30,"Overweight","Obesity"))) -> Underweight | V3: =IF(C3<5.7,"Normal",IF(C3<6.5,"Prediabetes","Diabetes")) -> Normal | X3: Smoker+No cancer | Y3: =COUNTIFS($H:$H,"Yes",$F:$F,"No") -> 404 | AJ3: No | AK3: =SUMIF($E:$E,"No",$G:$G) -> 1417 | AL3: =AVERAGEIF($E:$E,"No",$C:$C) -> 6.6704427 | AR3: Normal weight | AS3: =AVERAGEIF($U:$U,"Normalweight",$T:$T) -> 9851.9225 | AT3: Prediabetes | AU3: =AVERAGEIF($V:$V,"Prediabetes",$T:$T) -> 12532.263 | BB3: R1014 | BC3: =IFERROR(AVERAGEIFS('Health care'!$T:$T,'Health care'!$N:$N,$BB3,'Health care'!$L:$L,"*tier*1*"),0) -> 13891.86 | BD3: =IFERROR(AVERAGEIFS('Health care'!$T:$T,'Health care'!$N:$N,$BB3,'Health care'!$L:$L,"*tier*2*"),0) -> 2395.17 | BE3: =IFERROR(AVERAGEIFS('Health care'!$T:$T,'Health care'!$N:$N,$BB3,'Health care'!$L:$L,"*tier*3*"),0) -> 16950.485
A4: Id2333 | B4: =VLOOKUP($A4,'[1]Medical Examinations'!$A:$J,2,FALSE) -> 16.47 | C4: =VLOOKUP($A4,'[1]Medical Examinations'!$A:$J,3,FALSE) -> 6.35 | D4: =VLOOKUP($A4,'[3]Medical Examinations'!$A:$J,4,FALSE) -> No | E4: =VLOOKUP($A4,'[1]Medical Examinations'!$A:$J,5,FALSE) -> No | F4: =VLOOKUP($A4,'[1]Medical Examinations'!$A:$J,6,FALSE) -> Yes | G4: =VLOOKUP($A4,'[3]Medical Examinations'!$A:$J,7,FALSE) -> 1 | H4: =VLOOKUP($A4,'[1]Medical Examinations'!$A:$J,8,FALSE) -> No | I4: =VLOOKUP($A4,'[2]Hospitalisation Details'!$A:$K,2,FALSE) -> 1993 | J4: =VLOOKUP($A4,'[2]Hospitalisation Details'!$A:$K,3,FALSE) -> Jun | K4: =VLOOKUP($A4,'[2]Hospitalisation Details'!$A:$K,4,FALSE) -> 30 | L4: =VLOOKUP($A4,'[2]Hospitalisation Details'!$A:$K,7,FALSE) -> tier - 2 | M4: =VLOOKUP($A4,'[2]Hospitalisation Details'!A:$K,8,FALSE) -> tier - 1 | N4: =VLOOKUP($A4,'[2]Hospitalisation Details'!$A:$K,9,FALSE) -> R1013 | O4: =VLOOKUP($A4,'[2]Hospitalisation Details'!$A:$K,10,FALSE) -> 0 | P4: =VLOOKUP($A4,'[2]Hospitalisation Details'!A:$K,11,FALSE) -> 0 | Q4: =VLOOKUP($A4,'Customer Names'!$A:E,3,FALSE) -> Ms. | R4: =VLOOKUP($A4,'Customer Names'!$A:$E,4,FALSE) -> Julie | S4: =VLOOKUP($A4,'Customer Names'!$A:$E,5,FALSE) -> 0 | T4: =VLOOKUP($A4,'[2]Hospitalisation Details'!$A:$K,6,FALSE) -> 600 | U4: =IF(B4<18.5,"Underweight",IF(B4<25,"Normalweight",IF(B4<30,"Overweight","Obesity"))) -> Underweight | V4: =IF(C4<5.7,"Normal",IF(C4<6.5,"Prediabetes","Diabetes")) -> Prediabetes | X4: Non-smoker +Cancer | Y4: =COUNTIFS($H:$H,"No",$F:$F,"Yes") -> 307 | AR4: Overweight | AS4: =+AVERAGEIF($U:$U,"Overweight",$T:$T) -> 11435.413 | AT4: Diabetes | AU4: =AVERAGEIF($V:$V,"Diabetes",$T:$T) -> 16120.287 | BB4: R1015 | BC4: =IFERROR(AVERAGEIFS('Health care'!$T:$T,'Health care'!$N:$N,$BB4,'Health care'!$L:$L,"*tier*1*"),0) -> 21523.52 | BD4: =IFERROR(AVERAGEIFS('Health care'!$T:$T,'Health care'!$N:$N,$BB4,'Health care'!$L:$L,"*tier*2*"),0) -> 16433.907 | BE4: =IFERROR(AVERAGEIFS('Health care'!$T:$T,'Health care'!$N:$N,$BB4,'Health care'!$L:$L,"*tier*3*"),0) -> 7570.755
A5: Id2332 | B5: =VLOOKUP($A5,'[1]Medical Examinations'!$A:$J,2,FALSE) -> 17.7 | C5: =VLOOKUP($A5,'[1]Medical Examinations'!$A:$J,3,FALSE) -> 6.28 | D5: =VLOOKUP($A5,'[3]Medical Examinations'!$A:$J,4,FALSE) -> No | E5: =VLOOKUP($A5,'[1]Medical Examinations'!$A:$J,5,FALSE) -> No | F5: =VLOOKUP($A5,'[1]Medical Examinations'!$A:$J,6,FALSE) -> No | G5: =VLOOKUP($A5,'[3]Medical Examinations'!$A:$J,7,FALSE) -> 1 | H5: =VLOOKUP($A5,'[1]Medical Examinations'!$A:$J,8,FALSE) -> No | I5: =VLOOKUP($A5,'[2]Hospitalisation Details'!$A:$K,2,FALSE) -> 1992 | J5: =VLOOKUP($A5,'[2]Hospitalisation Details'!$A:$K,3,FALSE) -> Sep | K5: =VLOOKUP($A5,'[2]Hospitalisation Details'!$A:$K,4,FALSE) -> 13 | L5: =VLOOKUP($A5,'[2]Hospitalisation Details'!$A:$K,7,FALSE) -> tier - 3 | M5: =VLOOKUP($A5,'[2]Hospitalisation Details'!A:$K,8,FALSE) -> tier - 3 | N5: =VLOOKUP($A5,'[2]Hospitalisation Details'!$A:$K,9,FALSE) -> R1013 | O5: =VLOOKUP($A5,'[2]Hospitalisation Details'!$A:$K,10,FALSE) -> 0 | P5: =VLOOKUP($A5,'[2]Hospitalisation Details'!A:$K,11,FALSE) -> 0 | Q5: =VLOOKUP($A5,'Customer Names'!$A:E,3,FALSE) -> Mr | R5: =VLOOKUP($A5,'Customer Names'!$A:$E,4,FALSE) -> Juan | S5: =VLOOKUP($A5,'Customer Names'!$A:$E,5,FALSE) -> Gonzalez | T5: =VLOOKUP($A5,'[2]Hospitalisation Details'!$A:$K,6,FALSE) -> 604.54 | U5: =IF(B5<18.5,"Underweight",IF(B5<25,"Normalweight",IF(B5<30,"Overweight","Obesity"))) -> Underweight | V5: =IF(C5<5.7,"Normal",IF(C5<6.5,"Prediabetes","Diabetes")) -> Prediabetes | X5: Non-smoker + No Cancer | Y5: =COUNTIFS($H:$H,"No",$F:$F,"No") -> 1538 | AR5: Obesity | AS5: =AVERAGEIF($U:$U,"Obesity",$T:$T) -> 16661.463
A6: Id2331 | B6: =VLOOKUP($A6,'[1]Medical Examinations'!$A:$J,2,FALSE) -> 22.34 | C6: =VLOOKUP($A6,'[1]Medical Examinations'!$A:$J,3,FALSE) -> 5.57 | D6: =VLOOKUP($A6,'[3]Medical Examinations'!$A:$J,4,FALSE) -> No | E6: =VLOOKUP($A6,'[1]Medical Examinations'!$A:$J,5,FALSE) -> No | F6: =VLOOKUP($A6,'[1]Medical Examinations'!$A:$J,6,FALSE) -> No | G6: =VLOOKUP($A6,'[3]Medical Examinations'!$A:$J,7,FALSE) -> 1 | H6: =VLOOKUP($A6,'[1]Medical Examinations'!$A:$J,8,FALSE) -> No | I6: =VLOOKUP($A6,'[2]Hospitalisation Details'!$A:$K,2,FALSE) -> 1998 | J6: =VLOOKUP($A6,'[2]Hospitalisation Details'!$A:$K,3,FALSE) -> Jul | K6: =VLOOKUP($A6,'[2]Hospitalisation Details'!$A:$K,4,FALSE) -> 27 | L6: =VLOOKUP($A6,'[2]Hospitalisation Details'!$A:$K,7,FALSE) -> tier - 3 | M6: =VLOOKUP($A6,'[2]Hospitalisation Details'!A:$K,8,FALSE) -> tier - 3 | N6: =VLOOKUP($A6,'[2]Hospitalisation Details'!$A:$K,9,FALSE) -> R1013 | O6: =VLOOKUP($A6,'[2]Hospitalisation Details'!$A:$K,10,FALSE) -> 0 | P6: =VLOOKUP($A6,'[2]Hospitalisation Details'!A:$K,11,FALSE) -> 0 | Q6: =VLOOKUP($A6,'Customer Names'!$A:E,3,FALSE) -> Mr. | R6: =VLOOKUP($A6,'Customer Names'!$A:$E,4,FALSE) -> Jordan | S6: =VLOOKUP($A6,'Customer Names'!$A:$E,5,FALSE) -> 0 | T6: =VLOOKUP($A6,'[2]Hospitalisation Details'!$A:$K,6,FALSE) -> 637.26 | U6: =IF(B6<18.5,"Underweight",IF(B6<25,"Normalweight",IF(B6<30,"Overweight","Obesity"))) -> Normalweight | V6: =IF(C6<5.7,"Normal",IF(C6<6.5,"Prediabetes","Diabetes")) -> Normal
A7: Id2330 | B7: =VLOOKUP($A7,'[1]Medical Examinations'!$A:$J,2,FALSE) -> 22.24 | C7: =VLOOKUP($A7,'[1]Medical Examinations'!$A:$J,3,FALSE) -> 4.29 | D7: =VLOOKUP($A7,'[3]Medical Examinations'!$A:$J,4,FALSE) -> yes | E7: =VLOOKUP($A7,'[1]Medical Examinations'!$A:$J,5,FALSE) -> No | F7: =VLOOKUP($A7,'[1]Medical Examinations'!$A:$J,6,FALSE) -> No | G7: =VLOOKUP($A7,'[3]Medical Examinations'!$A:$J,7,FALSE) -> No major surgery | H7: =VLOOKUP($A7,'[1]Medical Examinations'!$A:$J,8,FALSE) -> No | I7: =VLOOKUP($A7,'[2]Hospitalisation Details'!$A:$K,2,FALSE) -> 2001 | J7: =VLOOKUP($A7,'[2]Hospitalisation Details'!$A:$K,3,FALSE) -> Nov | K7: =VLOOKUP($A7,'[2]Hospitalisation Details'!$A:$K,4,FALSE) -> 20 | L7: =VLOOKUP($A7,'[2]Hospitalisation Details'!$A:$K,7,FALSE) -> tier - 3 | M7: =VLOOKUP($A7,'[2]Hospitalisation Details'!A:$K,8,FALSE) -> tier - 3 | N7: =VLOOKUP($A7,'[2]Hospitalisation Details'!$A:$K,9,FALSE) -> R1012 | O7: =VLOOKUP($A7,'[2]Hospitalisation Details'!$A:$K,10,FALSE) -> 0 | P7: =VLOOKUP($A7,'[2]Hospitalisation Details'!A:$K,11,FALSE) -> 0 | Q7: =VLOOKUP($A7,'Customer Names'!$A:E,3,FALSE) -> Ms. | R7: =VLOOKUP($A7,'Customer Names'!$A:$E,4,FALSE) -> Katy | S7: =VLOOKUP($A7,'Customer Names'!$A:$E,5,FALSE) -> 0 | T7: =VLOOKUP($A7,'[2]Hospitalisation Details'!$A:$K,6,FALSE) -> 646.14 | U7: =IF(B7<18.5,"Underweight",IF(B7<25,"Normalweight",IF(B7<30,"Overweight","Obesity"))) -> Normalweight | V7: =IF(C7<5.7,"Normal",IF(C7<6.5,"Prediabetes","Diabetes")) -> Normal
A8: Id2329 | B8: =VLOOKUP($A8,'[1]Medical Examinations'!$A:$J,2,FALSE) -> 17.07 | C8: =VLOOKUP($A8,'[1]Medical Examinations'!$A:$J,3,FALSE) -> 5.22 | D8: =VLOOKUP($A8,'[3]Medical Examinations'!$A:$J,4,FALSE) -> No | E8: =VLOOKUP($A8,'[1]Medical Examinations'!$A:$J,5,FALSE) -> No | F8: =VLOOKUP($A8,'[1]Medical Examinations'!$A:$J,6,FALSE) -> Yes | G8: =VLOOKUP($A8,'[3]Medical Examinations'!$A:$J,7,FALSE) -> 1 | H8: =VLOOKUP($A8,'[1]Medical Examinations'!$A:$J,8,FALSE) -> No | I8: =VLOOKUP($A8,'[2]Hospitalisation Details'!$A:$K,2,FALSE) -> 1993 | J8: =VLOOKUP($A8,'[2]Hospitalisation Details'!$A:$K,3,FALSE) -> Jun | K8: =VLOOKUP($A8,'[2]Hospitalisation Details'!$A:$K,4,FALSE) -> 1 | L8: =VLOOKUP($A8,'[2]Hospitalisation Details'!$A:$K,7,FALSE) -> tier - 3 | M8: =VLOOKUP($A8,'[2]Hospitalisation Details'!A:$K,8,FALSE) -> tier - 3 | N8: =VLOOKUP($A8,'[2]Hospitalisation Details'!$A:$K,9,FALSE) -> R1013 | O8: =VLOOKUP($A8,'[2]Hospitalisation Details'!$A:$K,10,FALSE) -> 0 | P8: =VLOOKUP($A8,'[2]Hospitalisation Details'!A:$K,11,FALSE) -> 0 | Q8: =VLOOKUP($A8,'Customer Names'!$A:E,3,FALSE) -> Ms. | R8: =VLOOKUP($A8,'Customer Names'!$A:$E,4,FALSE) -> Susan | S8: =VLOOKUP($A8,'Customer Names'!$A:$E,5,FALSE) -> E | T8: =VLOOKUP($A8,'[2]Hospitalisation Details'!$A:$K,6,FALSE) -> 650 | U8: =IF(B8<18.5,"Underweight",IF(B8<25,"Normalweight",IF(B8<30,"Overweight","Obesity"))) -> Underweight | V8: =IF(C8<5.7,"Normal",IF(C8<6.5,"Prediabetes","Diabetes")) -> Normal
A9: Id2328 | B9: =VLOOKUP($A9,'[1]Medical Examinations'!$A:$J,2,FALSE) -> 17.82 | C9: =VLOOKUP($A9,'[1]Medical Examinations'!$A:$J,3,FALSE) -> 5.26 | D9: =VLOOKUP($A9,'[3]Medical Examinations'!$A:$J,4,FALSE) -> yes | E9: =VLOOKUP($A9,'[1]Medical Examinations'!$A:$J,5,FALSE) -> No | F9: =VLOOKUP($A9,'[1]Medical Examinations'!$A:$J,6,FALSE) -> No | G9: =VLOOKUP($A9,'[3]Medical Examinations'!$A:$J,7,FALSE) -> 1 | H9: =VLOOKUP($A9,'[1]Medical Examinations'!$A:$J,8,FALSE) -> No | I9: =VLOOKUP($A9,'[2]Hospitalisation Details'!$A:$K,2,FALSE) -> 1995 | J9: =VLOOKUP($A9,'[2]Hospitalisation Details'!$A:$K,3,FALSE) -> Jul | K9: =VLOOKUP($A9,'[2]Hospitalisation Details'!$A:$K,4,FALSE) -> 4 | L9: =VLOOKUP($A9,'[2]Hospitalisation Details'!$A:$K,7,FALSE) -> tier - 3 | M9: =VLOOKUP($A9,'[2]Hospitalisation Details'!A:$K,8,FALSE) -> tier - 3 | N9: =VLOOKUP($A9,'[2]Hospitalisation Details'!$A:$K,9,FALSE) -> R1013 | O9: =VLOOKUP($A9,'[2]Hospitalisation Details'!$A:$K,10,FALSE) -> 0 | P9: =VLOOKUP($A9,'[2]Hospitalisation Details'!A:$K,11,FALSE) -> 0 | Q9: =VLOOKUP($A9,'Customer Names'!$A:E,3,FALSE) -> Ms. | R9: =VLOOKUP($A9,'Customer Names'!$A:$E,4,FALSE) -> Nicole | S9: =VLOOKUP($A9,'Customer Names'!$A:$E,5,FALSE) -> 0 | T9: =VLOOKUP($A9,'[2]Hospitalisation Details'!$A:$K,6,FALSE) -> 650 | U9: =IF(B9<18.5,"Underweight",IF(B9<25,"Normalweight",IF(B9<30,"Overweight","Obesity"))) -> Underweight | V9: =IF(C9<5.7,"Normal",IF(C9<6.5,"Prediabetes","Diabetes")) -> Normal
A10: Id2327 | B10: =VLOOKUP($A10,'[1]Medical Examinations'!$A:$J,2,FALSE) -> 21.77 | C10: =VLOOKUP($A10,'[1]Medical Examinations'!$A:$J,3,FALSE) -> 10.67 | D10: =VLOOKUP($A10,'[3]Medical Examinations'!$A:$J,4,FALSE) -> No | E10: =VLOOKUP($A10,'[1]Medical Examinations'!$A:$J,5,FALSE) -> No | F10: =VLOOKUP($A10,'[1]Medical Examinations'!$A:$J,6,FALSE) -> No | G10: =VLOOKUP($A10,'[3]Medical Examinations'!$A:$J,7,FALSE) -> No major surgery | H10: =VLOOKUP($A10,'[1]Medical Examinations'!$A:$J,8,FALSE) -> No | I10: =VLOOKUP($A10,'[2]Hospitalisation Details'!$A:$K,2,FALSE) -> 2002 | J10: =VLOOKUP($A10,'[2]Hospitalisation Details'!$A:$K,3,FALSE) -> Nov | K10: =VLOOKUP($A10,'[2]Hospitalisation Details'!$A:$K,4,FALSE) -> 29 | L10: =VLOOKUP($A10,'[2]Hospitalisation Details'!$A:$K,7,FALSE) -> tier - 3 | M10: =VLOOKUP($A10,'[2]Hospitalisation Details'!A:$K,8,FALSE) -> tier - 2 | N10: =VLOOKUP($A10,'[2]Hospitalisation Details'!$A:$K,9,FALSE) -> R1012 | O10: =VLOOKUP($A10,'[2]Hospitalisation Details'!$A:$K,10,FALSE) -> 0 | P10: =VLOOKUP($A10,'[2]Hospitalisation Details'!A:$K,11,FALSE) -> 0 | Q10: =VLOOKUP($A10,'Customer Names'!$A:E,3,FALSE) -> Ms. | R10: =VLOOKUP($A10,'Customer Names'!$A:$E,4,FALSE) -> Laura | S10: =VLOOKUP($A10,'Customer Names'!$A:$E,5,FALSE) -> 0 | T10: =VLOOKUP($A10,'[2]Hospitalisation Details'!$A:$K,6,FALSE) -> 668 | U10: =IF(B10<18.5,"Underweight",IF(B10<25,"Normalweight",IF(B10<30,"Overweight","Obesity"))) -> Normalweight | V10: =IF(C10<5.7,"Normal",IF(C10<6.5,"Prediabetes","Diabetes")) -> Diabetes
A11: Id2326 | B11: =VLOOKUP($A11,'[1]Medical Examinations'!$A:$J,2,FALSE) -> 20.1 | C11: =VLOOKUP($A11,'[1]Medical Examinations'!$A:$J,3,FALSE) -> 5.6 | D11: =VLOOKUP($A11,'[3]Medical Examinations'!$A:$J,4,FALSE) -> yes | E11: =VLOOKUP($A11,'[1]Medical Examinations'!$A:$J,5,FALSE) -> No | F11: =VLOOKUP($A11,'[1]Medical Examinations'!$A:$J,6,FALSE) -> Yes | G11: =VLOOKUP($A11,'[3]Medical Examinations'!$A:$J,7,FALSE) -> 1 | H11: =VLOOKUP($A11,'[1]Medical Examinations'!$A:$J,8,FALSE) -> No | I11: =VLOOKUP($A11,'[2]Hospitalisation Details'!$A:$K,2,FALSE) -> 1997 | J11: =VLOOKUP($A11,'[2]Hospitalisation Details'!$A:$K,3,FALSE) -> Nov | K11: =VLOOKUP($A11,'[2]Hospitalisation Details'!$A:$K,4,FALSE) -> 9 | L11: =VLOOKUP($A11,'[2]Hospitalisation Details'!$A:$K,7,FALSE) -> tier - 3 | M11: =VLOOKUP($A11,'[2]Hospitalisation Details'!A:$K,8,FALSE) -> tier - 3 | N11: =VLOOKUP($A11,'[2]Hospitalisation Details'!$A:$K,9,FALSE) -> R1013 | O11: =VLOOKUP($A11,'[2]Hospitalisation Details'!$A:$K,10,FALSE) -> 0 | P11: =VLOOKUP($A11,'[2]Hospitalisation Details'!A:$K,11,FALSE) -> 0 | Q11: =VLOOKUP($A11,'Customer Names'!$A:E,3,FALSE) -> Mr. | R11: =VLOOKUP($A11,'Customer Names'!$A:$E,4,FALSE) -> Sebastian | S11: =VLOOKUP($A11,'Customer Names'!$A:$E,5,FALSE) -> 0 | T11: =VLOOKUP($A11,'[2]Hospitalisation Details'!$A:$K,6,FALSE) -> 670 | U11: =IF(B11<18.5,"Underweight",IF(B11<25,"Normalweight",IF(B11<30,"Overweight","Obesity"))) -> Normalweight | V11: =IF(C11<5.7,"Normal",IF(C11<6.5,"Prediabetes","Diabetes")) -> Normal
A12: Id2325 | B12: =VLOOKUP($A12,'[1]Medical Examinations'!$A:$J,2,FALSE) -> 24.76 | C12: =VLOOKUP($A12,'[1]Medical Examinations'!$A:$J,3,FALSE) -> 4.54 | D12: =VLOOKUP($A12,'[3]Medical Examinations'!$A:$J,4,FALSE) -> yes | E12: =VLOOKUP($A12,'[1]Medical Examinations'!$A:$J,5,FALSE) -> No | F12: =VLOOKUP($A12,'[1]Medical Examinations'!$A:$J,6,FALSE) -> No | G12: =VLOOKUP($A12,'[3]Medical Examinations'!$A:$J,7,FALSE) -> No major surgery | H12: =VLOOKUP($A12,'[1]Medical Examinations'!$A:$J,8,FALSE) -> No | I12: =VLOOKUP($A12,'[2]Hospitalisation Details'!$A:$K,2,FALSE) -> 2001 | J12: =VLOOKUP($A12,'[2]Hospitalisation Details'!$A:$K,3,FALSE) -> Sep | K12: =VLOOKUP($A12,'[2]Hospitalisation Details'!$A:$K,4,FALSE) -> 12 | L12: =VLOOKUP($A12,'[2]Hospitalisation Details'!$A:$K,7,FALSE) -> tier - 3 | M12: =VLOOKUP($A12,'[2]Hospitalisation Details'!A:$K,8,FALSE) -> tier - 2 | N12: =VLOOKUP($A12,'[2]Hospitalisation Details'!$A:$K,9,FALSE) -> R1013 | O12: =VLOOKUP($A12,'[2]Hospitalisation Details'!$A:$K,10,FALSE) -> 0 | P12: =VLOOKUP($A12,'[2]Hospitalisation Details'!A:$K,11,FALSE) -> 0 | Q12: =VLOOKUP($A12,'Customer Names'!$A:E,3,FALSE) -> Mr. | R12: =VLOOKUP($A12,'Customer Names'!$A:$E,4,FALSE) -> Fred | S12: =VLOOKUP($A12,'Customer Names'!$A:$E,5,FALSE) -> 0 | T12: =VLOOKUP($A12,'[2]Hospitalisation Details'!$A:$K,6,FALSE) -> 687.54 | U12: =IF(B12<18.5,"Underweight",IF(B12<25,"Normalweight",IF(B12<30,"Overweight","Obesity"))) -> Normalweight | V12: =IF(C12<5.7,"Normal",IF(C12<6.5,"Prediabetes","Diabetes")) -> Normal
A13: Id2324 | B13: =VLOOKUP($A13,'[1]Medical Examinations'!$A:$J,2,FALSE) -> 22.24 | C13: =VLOOKUP($A13,'[1]Medical Examinations'!$A:$J,3,FALSE) -> 5.04 | D13: =VLOOKUP($A13,'[3]Medical Examinations'!$A:$J,4,FALSE) -> No | E13: =VLOOKUP($A13,'[1]Medical Examinations'!$A:$J,5,FALSE) -> No | F13: =VLOOKUP($A13,'[1]Medical Examinations'!$A:$J,6,FALSE) -> No | G13: =VLOOKUP($A13,'[3]Medical Examinations'!$A:$J,7,FALSE) -> No major surgery | H13: =VLOOKUP($A13,'[1]Medical Examinations'!$A:$J,8,FALSE) -> No | I13: =VLOOKUP($A13,'[2]Hospitalisation Details'!$A:$K,2,FALSE) -> 1999 | J13: =VLOOKUP($A13,'[2]Hospitalisation Details'!$A:$K,3,FALSE) -> Dec | K13: =VLOOKUP($A13,'[2]Hospitalisation Details'!$A:$K,4,FALSE) -> 26 | L13: =VLOOKUP($A13,'[2]Hospitalisation Details'!$A:$K,7,FALSE) -> ? | M13: =VLOOKUP($A13,'[2]Hospitalisation Details'!A:$K,8,FALSE) -> tier - 3 | N13: =VLOOKUP($A13,'[2]Hospitalisation Details'!$A:$K,9,FALSE) -> R1013 | O13: =VLOOKUP($A13,'[2]Hospitalisation Details'!$A:$K,10,FALSE) -> 0 | P13: =VLOOKUP($A13,'[2]Hospitalisation Details'!A:$K,11,FALSE) -> 0 | Q13: =VLOOKUP($A13,'Customer Names'!$A:E,3,FALSE) -> Ms. | R13: =VLOOKUP($A13,'Customer Names'!$A:$E,4,FALSE) -> Meghan | S13: =VLOOKUP($A13,'Customer Names'!$A:$E,5,FALSE) -> K | T13: =VLOOKUP($A13,'[2]Hospitalisation Details'!$A:$K,6,FALSE) -> 700 | U13: =IF(B13<18.5,"Underweight",IF(B13<25,"Normalweight",IF(B13<30,"Overweight","Obesity"))) -> Normalweight | V13: =IF(C13<5.7,"Normal",IF(C13<6.5,"Prediabetes","Diabetes")) -> Normal
A14: Id2323 | B14: =VLOOKUP($A14,'[1]Medical Examinations'!$A:$J,2,FALSE) -> 23.35 | C14: =VLOOKUP($A14,'[1]Medical Examinations'!$A:$J,3,FALSE) -> 5.94 | D14: =VLOOKUP($A14,'[3]Medical Examinations'!$A:$J,4,FALSE) -> No | E14: =VLOOKUP($A14,'[1]Medical Examinations'!$A:$J,5,FALSE) -> No | F14: =VLOOKUP($A14,'[1]Medical Examinations'!$A:$J,6,FALSE) -> No | G14: =VLOOKUP($A14,'[3]Medical Examinations'!$A:$J,7,FALSE) -> No major surgery | H14: =VLOOKUP($A14,'[1]Medical Examinations'!$A:$J,8,FALSE) -> No | I14: =VLOOKUP($A14,'[2]Hospitalisation Details'!$A:$K,2,FALSE) -> 1999 | J14: =VLOOKUP($A14,'[2]Hospitalisation Details'!$A:$K,3,FALSE) -> Dec | K14: =VLOOKUP($A14,'[2]Hospitalisation Details'!$A:$K,4,FALSE) -> 14 | L14: =VLOOKUP($A14,'[2]Hospitalisation Details'!$A:$K,7,FALSE) -> tier - 3 | M14: =VLOOKUP($A14,'[2]Hospitalisation Details'!A:$K,8,FALSE) -> tier - 1 | N14: =VLOOKUP($A14,'[2]Hospitalisation Details'!$A:$K,9,FALSE) -> R1013 | O14: =VLOOKUP($A14,'[2]Hospitalisation Details'!$A:$K,10,FALSE) -> 0 | P14: =VLOOKUP($A14,'[2]Hospitalisation Details'!A:$K,11,FALSE) -> 0 | Q14: =VLOOKUP($A14,'Customer Names'!$A:E,3,FALSE) -> Mr. | R14: =VLOOKUP($A14,'Customer Names'!$A:$E,4,FALSE) -> Matthew | S14: =VLOOKUP($A14,'Customer Names'!$A:$E,5,FALSE) -> 0 | T14: =VLOOKUP($A14,'[2]Hospitalisation Details'!$A:$K,6,FALSE) -> 722.99 | U14: =IF(B14<18.5,"Underweight",IF(B14<25,"Normalweight",IF(B14<30,"Overweight","Obesity"))) -> Normalweight | V14: =IF(C14<5.7,"Normal",IF(C14<6.5,"Prediabetes","Diabetes")) -> Prediabetes
A15: Id2322 | B15: =VLOOKUP($A15,'[1]Medical Examinations'!$A:$J,2,FALSE) -> 21.38 | C15: =VLOOKUP($A15,'[1]Medical Examinations'!$A:$J,3,FALSE) -> 8.01 | D15: =VLOOKUP($A15,'[3]Medical Examinations'!$A:$J,4,FALSE) -> No | E15: =VLOOKUP($A15,'[1]Medical Examinations'!$A:$J,5,FALSE) -> No | F15: =VLOOKUP($A15,'[1]Medical Examinations'!$A:$J,6,FALSE) -> No | G15: =VLOOKUP($A15,'[3]Medical Examinations'!$A:$J,7,FALSE) -> No major surgery | H15: =VLOOKUP($A15,'[1]Medical Examinations'!$A:$J,8,FALSE) -> No | I15: =VLOOKUP($A15,'[2]Hospitalisation Details'!$A:$K,2,FALSE) -> 2002 | J15: =VLOOKUP($A15,'[2]Hospitalisation Details'!$A:$K,3,FALSE) -> ? | K15: =VLOOKUP($A15,'[2]Hospitalisation Details'!$A:$K,4,FALSE) -> 19 | L15: =VLOOKUP($A15,'[2]Hospitalisation Details'!$A:$K,7,FALSE) -> tier - 3 | M15: =VLOOKUP($A15,'[2]Hospitalisation Details'!A:$K,8,FALSE) -> tier - 1 | N15: =VLOOKUP($A15,'[2]Hospitalisation Details'!$A:$K,9,FALSE) -> R1012 | O15: =VLOOKUP($A15,'[2]Hospitalisation Details'!$A:$K,10,FALSE) -> 0 | P15: =VLOOKUP($A15,'[2]Hospitalisation Details'!A:$K,11,FALSE) -> 0 | Q15: =VLOOKUP($A15,'Customer Names'!$A:E,3,FALSE) -> Ms. | R15: =VLOOKUP($A15,'Customer Names'!$A:$E,4,FALSE) -> Holly | S15: =VLOOKUP($A15,'Customer Names'!$A:$E,5,FALSE) -> 0 | T15: =VLOOKUP($A15,'[2]Hospitalisation Details'!$A:$K,6,FALSE) -> 750 | U15: =IF(B15<18.5,"Underweight",IF(B15<25,"Normalweight",IF(B15<30,"Overweight","Obesity"))) -> Normalweight | V15: =IF(C15<5.7,"Normal",IF(C15<6.5,"Prediabetes","Diabetes")) -> Diabetes
A16: Id2321 | B16: =VLOOKUP($A16,'[1]Medical Examinations'!$A:$J,2,FALSE) -> 17.86 | C16: =VLOOKUP($A16,'[1]Medical Examinations'!$A:$J,3,FALSE) -> 5.43 | D16: =VLOOKUP($A16,'[3]Medical Examinations'!$A:$J,4,FALSE) -> No | E16: =VLOOKUP($A16,'[1]Medical Examinations'!$A:$J,5,FALSE) -> No | F16: =VLOOKUP($A16,'[1]Medical Examinations'!$A:$J,6,FALSE) -> Yes | G16: =VLOOKUP($A16,'[3]Medical Examinations'!$A:$J,7,FALSE) -> 1 | H16: =VLOOKUP($A16,'[1]Medical Examinations'!$A:$J,8,FALSE) -> No | I16: =VLOOKUP($A16,'[2]Hospitalisation Details'!$A:$K,2,FALSE) -> 1993 | J16: =VLOOKUP($A16,'[2]Hospitalisation Details'!$A:$K,3,FALSE) -> Aug | K16: =VLOOKUP($A16,'[2]Hospitalisation Details'!$A:$K,4,FALSE) -> 9 | L16: =VLOOKUP($A16,'[2]Hospitalisation Details'!$A:$K,7,FALSE) -> tier - 3 | M16: =VLOOKUP($A16,'[2]Hospitalisation Details'!A:$K,8,FALSE) -> tier - 1 | N16: =VLOOKUP($A16,'[2]Hospitalisation Details'!$A:$K,9,FALSE) -> R1013 | O16: =VLOOKUP($A16,'[2]Hospitalisation Details'!$A:$K,10,FALSE) -> 0 | P16: =VLOOKUP($A16,'[2]Hospitalisation Details'!A:$K,11,FALSE) -> 0 | Q16: =VLOOKUP($A16,'Customer Names'!$A:E,3,FALSE) -> Mr. | R16: =VLOOKUP($A16,'Customer Names'!$A:$E,4,FALSE) -> Thomas | S16: =VLOOKUP($A16,'Customer Names'!$A:$E,5,FALSE) -> 0 | T16: =VLOOKUP($A16,'[2]Hospitalisation Details'!$A:$K,6,FALSE) -> 760 | U16: =IF(B16<18.5,"Underweight",IF(B16<25,"Normalweight",IF(B16<30,"Overweight","Obesity"))) -> Underweight | V16: =IF(C16<5.7,"Normal",IF(C16<6.5,"Prediabetes","Diabetes")) -> Normal
A17: Id2320 | B17: =VLOOKUP($A17,'[1]Medical Examinations'!$A:$J,2,FALSE) -> 19.21 | C17: =VLOOKUP($A17,'[1]Medical Examinations'!$A:$J,3,FALSE) -> 5.53 | D17: =VLOOKUP($A17,'[3]Medical Examinations'!$A:$J,4,FALSE) -> yes | E17: =VLOOKUP($A17,'[1]Medical Examinations'!$A:$J,5,FALSE) -> No | F17: =VLOOKUP($A17,'[1]Medical Examinations'!$A:$J,6,FALSE) -> No | G17: =VLOOKUP($A17,'[3]Medical Examinations'!$A:$J,7,FALSE) -> No major surgery | H17: =VLOOKUP($A17,'[1]Medical Examinations'!$A:$J,8,FALSE) -> No | I17: =VLOOKUP($A17,'[2]Hospitalisation Details'!$A:$K,2,FALSE) -> 1996 | J17: =VLOOKUP($A17,'[2]Hospitalisation Details'!$A:$K,3,FALSE) -> Oct | K17: =VLOOKUP($A17,'[2]Hospitalisation Details'!$A:$K,4,FALSE) -> 22 | L17: =VLOOKUP($A17,'[2]Hospitalisation Details'!$A:$K,7,FALSE) -> tier - 3 | M17: =VLOOKUP($A17,'[2]Hospitalisation Details'!A:$K,8,FALSE) -> tier - 3 | N17: =VLOOKUP($A17,'[2]Hospitalisation Details'!$A:$K,9,FALSE) -> R1013 | O17: =VLOOKUP($A17,'[2]Hospitalisation Details'!$A:$K,10,FALSE) -> 0 | P17: =VLOOKUP($A17,'[2]Hospitalisation Details'!A:$K,11,FALSE) -> 0 | Q17: =VLOOKUP($A17,'Customer Names'!$A:E,3,FALSE) -> Ms. | R17: =VLOOKUP($A17,'Customer Names'!$A:$E,4,FALSE) -> Lindy Rostro | S17: =VLOOKUP($A17,'Customer Names'!$A:$E,5,FALSE) -> 0 | T17: =VLOOKUP($A17,'[2]Hospitalisation Details'!$A:$K,6,FALSE) -> 760 | U17: =IF(B17<18.5,"Underweight",IF(B17<25,"Normalweight",IF(B17<30,"Overweight","Obesity"))) -> Normalweight | V17: =IF(C17<5.7,"Normal",IF(C17<6.5,"Prediabetes","Diabetes")) -> Normal
... A2343: Id2 | B2343: =VLOOKUP($A2343,'[1]Medical Examinations'!$A:$J,2,FALSE) -> 30.36 | C2343: =VLOOKUP($A2343,'[1]Medical Examinations'!$A:$J,3,FALSE) -> 5.77 | D2343: =VLOOKUP($A2343,'[3]Medical Examinations'!$A:$J,4,FALSE) -> No | E2343: =VLOOKUP($A2343,'[1]Medical Examinations'!$A:$J,5,FALSE) -> No | F2343: =VLOOKUP($A2343,'[1]Medical Examinations'!$A:$J,6,FALSE) -> No | G2343: =VLOOKUP($A2343,'[3]Medical Examinations'!$A:$J,7,FALSE) -> No major surgery | H2343: =VLOOKUP($A2343,'[1]Medical Examinations'!$A:$J,8,FALSE) -> yes | I2343: =VLOOKUP($A2343,'[2]Hospitalisation Details'!$A:$K,2,FALSE) -> 1977 | J2343: =VLOOKUP($A2343,'[2]Hospitalisation Details'!$A:$K,3,FALSE) -> Jun | K2343: =VLOOKUP($A2343,'[2]Hospitalisation Details'!$A:$K,4,FALSE) -> 8 | L2343: =VLOOKUP($A2343,'[2]Hospitalisation Details'!$A:$K,7,FALSE) -> tier - 2 | M2343: =VLOOKUP($A2343,'[2]Hospitalisation Details'!A:$K,8,FALSE) -> tier - 3 | N2343: =VLOOKUP($A2343,'[2]Hospitalisation Details'!$A:$K,9,FALSE) -> R1013 | O2343: =VLOOKUP($A2343,'[2]Hospitalisation Details'!$A:$K,10,FALSE) -> 0 | P2343: =VLOOKUP($A2343,'[2]Hospitalisation Details'!A:$K,11,FALSE) -> 0 | Q2343: =VLOOKUP($A2343,'Customer Names'!$A:E,3,FALSE) -> Mr. | R2343: =VLOOKUP($A2343,'Customer Names'!$A:$E,4,FALSE) -> Matthew | S2343: =VLOOKUP($A2343,'Customer Names'!$A:$E,5,FALSE) -> D | T2343: =VLOOKUP($A2343,'[2]Hospitalisation Details'!$A:$K,6,FALSE) -> 62592.87 | U2343: =IF(B2343<18.5,"Underweight",IF(B2343<25,"Normalweight",IF(B2343<30,"Overweight","Obesity"))) -> Obesity | V2343: =IF(C2343<5.7,"Normal",IF(C2343<6.5,"Prediabetes","Diabetes")) -> Prediabetes
A2344: Id1 | B2344: =VLOOKUP($A2344,'[1]Medical Examinations'!$A:$J,2,FALSE) -> 47.41 | C2344: =VLOOKUP($A2344,'[1]Medical Examinations'!$A:$J,3,FALSE) -> 7.47 | D2344: =VLOOKUP($A2344,'[3]Medical Examinations'!$A:$J,4,FALSE) -> No | E2344: =VLOOKUP($A2344,'[1]Medical Examinations'!$A:$J,5,FALSE) -> No | F2344: =VLOOKUP($A2344,'[1]Medical Examinations'!$A:$J,6,FALSE) -> No | G2344: =VLOOKUP($A2344,'[3]Medical Examinations'!$A:$J,7,FALSE) -> No major surgery | H2344: =VLOOKUP($A2344,'[1]Medical Examinations'!$A:$J,8,FALSE) -> yes | I2344: =VLOOKUP($A2344,'[2]Hospitalisation Details'!$A:$K,2,FALSE) -> 1968 | J2344: =VLOOKUP($A2344,'[2]Hospitalisation Details'!$A:$K,3,FALSE) -> Oct | K2344: =VLOOKUP($A2344,'[2]Hospitalisation Details'!$A:$K,4,FALSE) -> 12 | L2344: =VLOOKUP($A2344,'[2]Hospitalisation Details'!$A:$K,7,FALSE) -> tier - 1 | M2344: =VLOOKUP($A2344,'[2]Hospitalisation Details'!A:$K,8,FALSE) -> tier - 3 | N2344: =VLOOKUP($A2344,'[2]Hospitalisation Details'!$A:$K,9,FALSE) -> R1013 | O2344: =VLOOKUP($A2,'[2]Hospitalisation Details'!$A:$K,11,FALSE) -> 0 | P2344: =VLOOKUP($A2344,'[2]Hospitalisation Details'!A:$K,11,FALSE) -> 0 | Q2344: =VLOOKUP($A2344,'Customer Names'!$A:E,3,FALSE) -> Ms. | R2344: =VLOOKUP($A2344,'Customer Names'!$A:$E,4,FALSE) -> Kelly | S2344: =VLOOKUP($A2344,'Customer Names'!$A:$E,5,FALSE) -> 0 | T2344: =VLOOKUP($A2344,'[2]Hospitalisation Details'!$A:$K,6,FALSE) -> 63770.43 | U2344: =IF(B2344<18.5,"Underweight",IF(B2344<25,"Normalweight",IF(B2344<30,"Overweight","Obesity"))) -> Obesity | V2344: =IF(C2344<5.7,"Normal",IF(C2344<6.5,"Prediabetes","Diabetes")) -> Diabetes
